2024-09-29 11:25:10,818 - ERROR - [2024-Sep-29 11:25] 127.0.0.1 PUT http /? 5xx INTERNAL SERVER ERROR
Traceback (most recent call last):
  File "C:\Users\Home\Downloads\UserAPI\venv\lib\site-packages\flask\app.py", line 880, in full_dispatch_request
    rv = self.dispatch_request()
  File "C:\Users\Home\Downloads\UserAPI\venv\lib\site-packages\flask\app.py", line 865, in dispatch_request
    return self.ensure_sync(self.view_functions[rule.endpoint])(**view_args)  # type: ignore[no-any-return]
  File "C:/Users/Home/Downloads/UserAPI/app.py", line 46, in update_user
    new_email = request.json['new_email']
KeyError: 'new_email'

2024-09-29 13:41:28,832 - INFO - 127.0.0.1 POST http /? 400 BAD REQUEST
2024-09-29 13:45:54,560 - ERROR - [2024-Sep-29 13:45] 127.0.0.1 POST http /? 5xx INTERNAL SERVER ERROR
Traceback (most recent call last):
  File "C:\Users\Home\Downloads\UserAPI\venv\lib\site-packages\werkzeug\wrappers\request.py", line 608, in get_json
    rv = self.json_module.loads(data)
  File "C:\Users\Home\Downloads\UserAPI\venv\lib\site-packages\flask\json\provider.py", line 187, in loads
    return json.loads(s, **kwargs)
  File "C:\Users\Home\AppData\Local\Programs\Python\Python38-32\lib\json\__init__.py", line 357, in loads
    return _default_decoder.decode(s)
  File "C:\Users\Home\AppData\Local\Programs\Python\Python38-32\lib\json\decoder.py", line 337, in decode
    obj, end = self.raw_decode(s, idx=_w(s, 0).end())
  File "C:\Users\Home\AppData\Local\Programs\Python\Python38-32\lib\json\decoder.py", line 355, in raw_decode
    raise JSONDecodeError("Expecting value", s, err.value) from None
json.decoder.JSONDecodeError: Expecting value: line 1 column 1 (char 0)

During handling of the above exception, another exception occurred:

Traceback (most recent call last):
  File "C:\Users\Home\Downloads\UserAPI\venv\lib\site-packages\flask\wrappers.py", line 131, in on_json_loading_failed
    return super().on_json_loading_failed(e)
  File "C:\Users\Home\Downloads\UserAPI\venv\lib\site-packages\werkzeug\wrappers\request.py", line 642, in on_json_loading_failed
    raise BadRequest(f"Failed to decode JSON object: {e}")
werkzeug.exceptions.BadRequest: 400 Bad Request: Failed to decode JSON object: Expecting value: line 1 column 1 (char 0)

The above exception was the direct cause of the following exception:

Traceback (most recent call last):
  File "C:\Users\Home\Downloads\UserAPI\venv\lib\site-packages\flask\app.py", line 880, in full_dispatch_request
    rv = self.dispatch_request()
  File "C:\Users\Home\Downloads\UserAPI\venv\lib\site-packages\flask\app.py", line 865, in dispatch_request
    return self.ensure_sync(self.view_functions[rule.endpoint])(**view_args)  # type: ignore[no-any-return]
  File "C:/Users/Home/Downloads/UserAPI/app.py", line 53, in create_user
    user = User(request.json['first'], request.json['last'], request.json['email'])
  File "C:\Users\Home\Downloads\UserAPI\venv\lib\site-packages\werkzeug\wrappers\request.py", line 557, in json
    return self.get_json()
  File "C:\Users\Home\Downloads\UserAPI\venv\lib\site-packages\werkzeug\wrappers\request.py", line 617, in get_json
    rv = self.on_json_loading_failed(e)
  File "C:\Users\Home\Downloads\UserAPI\venv\lib\site-packages\flask\wrappers.py", line 136, in on_json_loading_failed
    raise BadRequest() from e
werkzeug.exceptions.BadRequest: 400 Bad Request: The browser (or proxy) sent a request that this server could not understand.

2024-09-29 14:21:01,866 - INFO - 127.0.0.1 POST http /? 400 BAD REQUEST
2024-09-29 14:23:29,769 - ERROR - [2024-Sep-29 14:23] 127.0.0.1 POST http /? 5xx INTERNAL SERVER ERROR
Traceback (most recent call last):
  File "C:\Users\Home\Downloads\UserAPI\venv\lib\site-packages\werkzeug\wrappers\request.py", line 608, in get_json
    rv = self.json_module.loads(data)
  File "C:\Users\Home\Downloads\UserAPI\venv\lib\site-packages\flask\json\provider.py", line 187, in loads
    return json.loads(s, **kwargs)
  File "C:\Users\Home\AppData\Local\Programs\Python\Python38-32\lib\json\__init__.py", line 357, in loads
    return _default_decoder.decode(s)
  File "C:\Users\Home\AppData\Local\Programs\Python\Python38-32\lib\json\decoder.py", line 337, in decode
    obj, end = self.raw_decode(s, idx=_w(s, 0).end())
  File "C:\Users\Home\AppData\Local\Programs\Python\Python38-32\lib\json\decoder.py", line 355, in raw_decode
    raise JSONDecodeError("Expecting value", s, err.value) from None
json.decoder.JSONDecodeError: Expecting value: line 1 column 1 (char 0)

During handling of the above exception, another exception occurred:

Traceback (most recent call last):
  File "C:\Users\Home\Downloads\UserAPI\venv\lib\site-packages\flask\wrappers.py", line 131, in on_json_loading_failed
    return super().on_json_loading_failed(e)
  File "C:\Users\Home\Downloads\UserAPI\venv\lib\site-packages\werkzeug\wrappers\request.py", line 642, in on_json_loading_failed
    raise BadRequest(f"Failed to decode JSON object: {e}")
werkzeug.exceptions.BadRequest: 400 Bad Request: Failed to decode JSON object: Expecting value: line 1 column 1 (char 0)

The above exception was the direct cause of the following exception:

Traceback (most recent call last):
  File "C:\Users\Home\Downloads\UserAPI\venv\lib\site-packages\flask\app.py", line 880, in full_dispatch_request
    rv = self.dispatch_request()
  File "C:\Users\Home\Downloads\UserAPI\venv\lib\site-packages\flask\app.py", line 865, in dispatch_request
    return self.ensure_sync(self.view_functions[rule.endpoint])(**view_args)  # type: ignore[no-any-return]
  File "C:/Users/Home/Downloads/UserAPI/app.py", line 52, in create_user
    if 'username' in request.get_json() and 'email' in request.get_json() and 'password' in request.get_json():
  File "C:\Users\Home\Downloads\UserAPI\venv\lib\site-packages\werkzeug\wrappers\request.py", line 617, in get_json
    rv = self.on_json_loading_failed(e)
  File "C:\Users\Home\Downloads\UserAPI\venv\lib\site-packages\flask\wrappers.py", line 136, in on_json_loading_failed
    raise BadRequest() from e
werkzeug.exceptions.BadRequest: 400 Bad Request: The browser (or proxy) sent a request that this server could not understand.

2024-09-29 14:31:52,150 - INFO - 127.0.0.1 POST http /? 400 BAD REQUEST
2024-09-29 14:32:19,421 - INFO - 127.0.0.1 POST http /? 200 OK
2024-09-29 14:33:55,890 - INFO - 127.0.0.1 POST http /? 200 OK
2024-09-29 14:34:12,077 - ERROR - [2024-Sep-29 14:34] 127.0.0.1 POST http /? 5xx INTERNAL SERVER ERROR
Traceback (most recent call last):
  File "C:\Users\Home\Downloads\UserAPI\venv\lib\site-packages\werkzeug\wrappers\request.py", line 608, in get_json
    rv = self.json_module.loads(data)
  File "C:\Users\Home\Downloads\UserAPI\venv\lib\site-packages\flask\json\provider.py", line 187, in loads
    return json.loads(s, **kwargs)
  File "C:\Users\Home\AppData\Local\Programs\Python\Python38-32\lib\json\__init__.py", line 357, in loads
    return _default_decoder.decode(s)
  File "C:\Users\Home\AppData\Local\Programs\Python\Python38-32\lib\json\decoder.py", line 337, in decode
    obj, end = self.raw_decode(s, idx=_w(s, 0).end())
  File "C:\Users\Home\AppData\Local\Programs\Python\Python38-32\lib\json\decoder.py", line 355, in raw_decode
    raise JSONDecodeError("Expecting value", s, err.value) from None
json.decoder.JSONDecodeError: Expecting value: line 1 column 1 (char 0)

During handling of the above exception, another exception occurred:

Traceback (most recent call last):
  File "C:\Users\Home\Downloads\UserAPI\venv\lib\site-packages\flask\wrappers.py", line 131, in on_json_loading_failed
    return super().on_json_loading_failed(e)
  File "C:\Users\Home\Downloads\UserAPI\venv\lib\site-packages\werkzeug\wrappers\request.py", line 642, in on_json_loading_failed
    raise BadRequest(f"Failed to decode JSON object: {e}")
werkzeug.exceptions.BadRequest: 400 Bad Request: Failed to decode JSON object: Expecting value: line 1 column 1 (char 0)

The above exception was the direct cause of the following exception:

Traceback (most recent call last):
  File "C:\Users\Home\Downloads\UserAPI\venv\lib\site-packages\flask\app.py", line 880, in full_dispatch_request
    rv = self.dispatch_request()
  File "C:\Users\Home\Downloads\UserAPI\venv\lib\site-packages\flask\app.py", line 865, in dispatch_request
    return self.ensure_sync(self.view_functions[rule.endpoint])(**view_args)  # type: ignore[no-any-return]
  File "C:/Users/Home/Downloads/UserAPI/app.py", line 53, in create_user
    if str(request.get_data()) in request.get_json() and 'email' in request.get_json() and 'password' in request.get_json():
  File "C:\Users\Home\Downloads\UserAPI\venv\lib\site-packages\werkzeug\wrappers\request.py", line 617, in get_json
    rv = self.on_json_loading_failed(e)
  File "C:\Users\Home\Downloads\UserAPI\venv\lib\site-packages\flask\wrappers.py", line 136, in on_json_loading_failed
    raise BadRequest() from e
werkzeug.exceptions.BadRequest: 400 Bad Request: The browser (or proxy) sent a request that this server could not understand.

2024-09-29 20:19:57,871 - INFO - 127.0.0.1 POST http /? 200 OK
2024-09-29 20:22:45,721 - INFO - 127.0.0.1 POST http /? 200 OK
2024-09-29 20:24:41,074 - INFO - 127.0.0.1 POST http /? 200 OK
2024-09-29 20:25:07,730 - INFO - 127.0.0.1 POST http /? 200 OK
2024-09-29 20:28:48,913 - INFO - 127.0.0.1 POST http /? 400 BAD REQUEST
2024-09-29 20:29:12,042 - INFO - 127.0.0.1 POST http /? 400 BAD REQUEST
2024-09-29 20:29:37,496 - INFO - 127.0.0.1 POST http /? 400 BAD REQUEST
2024-09-29 20:40:26,666 - INFO - 127.0.0.1 POST http /? 200 OK
2024-09-29 20:41:10,377 - INFO - 127.0.0.1 POST http /? 200 OK
2024-09-29 20:41:26,534 - INFO - 127.0.0.1 POST http /? 200 OK
2024-09-29 20:42:02,410 - INFO - 127.0.0.1 POST http /? 200 OK
2024-09-29 20:42:47,354 - INFO - 127.0.0.1 POST http /? 409 CONFLICT
2024-09-29 20:47:40,785 - INFO - 127.0.0.1 POST http /? 422 UNPROCESSABLE ENTITY
2024-09-29 20:47:45,908 - INFO - 127.0.0.1 POST http /? 422 UNPROCESSABLE ENTITY
2024-09-29 20:47:49,662 - INFO - 127.0.0.1 POST http /? 409 CONFLICT
2024-09-29 20:50:35,257 - INFO - 127.0.0.1 POST http /? 409 CONFLICT
2024-09-29 20:52:50,298 - INFO - 127.0.0.1 POST http /? 409 CONFLICT
2024-09-29 21:33:12,163 - INFO - 127.0.0.1 PUT http /? 200 OK
2024-09-29 21:41:05,756 - INFO - 127.0.0.1 PUT http /? 404 NOT FOUND
2024-09-29 21:41:38,086 - INFO - 127.0.0.1 PUT http /? 422 UNPROCESSABLE ENTITY
2024-09-29 21:43:59,592 - INFO - 127.0.0.1 PUT http /? 404 NOT FOUND
2024-09-29 21:55:03,287 - INFO - 127.0.0.1 PUT http /? 422 UNPROCESSABLE ENTITY
2024-09-29 21:55:15,125 - INFO - 127.0.0.1 PUT http /? 422 UNPROCESSABLE ENTITY
2024-09-29 21:57:30,588 - INFO - 127.0.0.1 PUT http /? 422 UNPROCESSABLE ENTITY
2024-09-29 21:59:45,314 - INFO - 127.0.0.1 PUT http /? 422 UNPROCESSABLE ENTITY
2024-09-29 23:06:38,529 - INFO - 127.0.0.1 PUT http /? 422 UNPROCESSABLE ENTITY
2024-09-29 23:12:50,370 - INFO - 127.0.0.1 DELETE http /? 200 OK
2024-09-29 23:26:47,459 - INFO - 127.0.0.1 DELETE http /? 200 OK
2024-09-29 23:27:02,490 - INFO - 127.0.0.1 DELETE http /? 200 OK
2024-09-29 23:28:54,827 - INFO - 127.0.0.1 DELETE http /? 422 UNPROCESSABLE ENTITY
2024-09-29 23:30:34,355 - INFO - 127.0.0.1 DELETE http /? 422 UNPROCESSABLE ENTITY
2024-09-29 23:33:21,463 - INFO - 127.0.0.1 DELETE http /? 200 OK
2024-09-29 23:34:08,092 - INFO - 127.0.0.1 DELETE http /? 422 UNPROCESSABLE ENTITY
2024-09-29 23:34:08,094 - INFO - 127.0.0.1 DELETE http /? 422 UNPROCESSABLE ENTITY
2024-09-29 23:34:14,275 - INFO - 127.0.0.1 DELETE http /? 200 OK
2024-09-29 23:44:45,616 - INFO - 127.0.0.1 DELETE http /? 404 NOT FOUND
2024-09-29 23:45:03,696 - INFO - 127.0.0.1 DELETE http /? 404 NOT FOUND
2024-09-30 12:51:42,450 - INFO - 127.0.0.1 DELETE http /? 404 NOT FOUND
2024-09-30 12:51:49,351 - INFO - 127.0.0.1 DELETE http /? 404 NOT FOUND
2024-09-30 12:51:57,921 - INFO - 127.0.0.1 DELETE http /? 404 NOT FOUND
2024-09-30 12:52:04,125 - INFO - 127.0.0.1 POST http /? 200 OK
2024-09-30 12:52:23,707 - INFO - 127.0.0.1 PUT http /? 422 UNPROCESSABLE ENTITY
2024-09-30 12:52:26,948 - INFO - 127.0.0.1 PUT http /? 422 UNPROCESSABLE ENTITY
2024-09-30 12:52:34,132 - INFO - 127.0.0.1 GET http /? 200 OK
2024-09-30 12:53:11,934 - INFO - 127.0.0.1 GET http /? 200 OK
